---
projects: [c-pac-on-habanero, c-pac-user-support, c-pac, this-notebook]
author: [Jon Clucas]
date: 2020-06-30
---

- [x] review Habanero test ‚Äî [{% octicon git-pull-request height:12 class:"right left" aria-label:PR %} #1312](https://github.com/FCP-INDI/C-PAC/pull/1312); :email: emailed results and image to Columbia team.
- [x] fix Singularity recipe ‚Äî [{% octicon git-pull-request height:12 class:"right left" aria-label:PR %} #1311](https://github.com/FCP-INDI/C-PAC/pull/1311)
- [x] spec [automated testing strategy]({{ site.baseurl }}/specs/c-pac-testing.html)
- [x] [review Habanero 2/2]({{ site.baseurl }}/log/2020-06-30.html#review-habanero-22) ‚Äî [{% octicon git-pull-request height:12 class:"right left" aria-label:PR %} #1313](https://github.com/FCP-INDI/C-PAC/pull/1313); :email: emailed response

<!--more-->

### didn't get to:

- [ ] wrap up versioned / restructured user + developer docs
- [ ] simplify automated testing (C-PAC)
- [ ] fix Docker issue in Python package
- [ ] NMIND
  - [ ] coding standards
  - [ ] testing standards
- [ ] spec Docker image for testing

---

## C-PAC user support

<div class="keep-together" markdown="1">
### review Habanero test

(cont'd from [yesterday](http://localhost:4000/lab-notebook/log/2020-06-29.html#review-habanero-test))

<div class="pencil" markdown="1">
I wonder if participant 19 is a data or data configuration issue?
</div>

[results](https://app.circleci.com/pipelines/github/shnizzedy/C-PAC/98/workflows/87b2ac35-aabc-428c-9fea-9b38cf0488db):

<table class="success-fail">
  <tr><th>participant_ndx</th><th>Singularity</th><th>Docker</th></tr>
  <tr><td>1</td><td class="success"></td><td class="success"></td></tr>
  <tr><td>2</td><td class="success"></td><td class="success"></td></tr>
  <tr><td>3</td><td class="success"></td><td class="success"></td></tr>
  <tr><td>4</td><td class="success"></td><td class="success"></td></tr>
  <tr><td>5</td><td class="success"></td><td class="success"></td></tr>
  <tr><td>6</td><td class="success"></td><td class="success"></td></tr>
  <tr><td>7</td><td class="success"></td><td class="success"></td></tr>
  <tr><td>8</td><td class="success"></td><td class="success"></td></tr>
  <tr><td>9</td><td class="success"></td><td class="success"></td></tr>
  <tr><td>10</td><td class="success"></td><td class="success"></td></tr>
  <tr><td>11</td><td class="success"></td><td class="success"></td></tr>
  <tr><td>12</td><td class="success"></td><td class="success"></td></tr>
  <tr><td>13</td><td class="success"></td><td class="success"></td></tr>
  <tr><td>14</td><td class="success"></td><td class="success"></td></tr>
  <tr><td>15</td><td class="success"></td><td class="success"></td></tr>
  <tr><td>16</td><td class="failure"><a href="https://github.com/FCP-INDI/C-PAC/issues/1256">#1256</a></td><td class="failure"><a href="https://github.com/FCP-INDI/C-PAC/issues/1256">#1256</a></td></tr>
  <tr><td>17</td><td class="success"></td><td class="success"></td></tr>
  <tr><td>18</td><td class="success"></td><td class="success"></td></tr>
  <tr><td>19</td><td class="failure"></td><td class="failure"></td></tr>
  <tr><td>20</td><td class="success"></td><td class="success"></td></tr>
</table>

#### Participant 16

[‚ìà Singularity](https://app.circleci.com/pipelines/github/shnizzedy/C-PAC/98/workflows/87b2ac35-aabc-428c-9fea-9b38cf0488db/jobs/647/artifacts)
[üê≥ Docker](https://app.circleci.com/pipelines/github/shnizzedy/C-PAC/98/workflows/87b2ac35-aabc-428c-9fea-9b38cf0488db/jobs/655/artifacts)

```BASH
[Node] Finished "resting_preproc_A00040573_NFB3.sinker_0_qc___mni_normalized_anatomical_a".
200630-05:55:02,941 nipype.workflow INFO:
***********************************
200630-05:55:02,941 nipype.workflow ERROR:
could not run node: resting_preproc_A00040573_NFB3.nuisance_regressor_2_0.build_nuisance_regressors.a0.b0
200630-05:55:02,941 nipype.workflow INFO:
crashfile: /output/crash/crash-20200630-055241-root-build_nuisance_regressors.a0.b0-d59e91b4-ba0a-43b1-a411-6791f9e2d439.pklz
200630-05:55:02,942 nipype.workflow ERROR:
could not run node: resting_preproc_A00040573_NFB3.nuisance_regressor_1_0.build_nuisance_regressors.a0.b0
200630-05:55:02,942 nipype.workflow INFO:
crashfile: /output/crash/crash-20200630-055302-root-build_nuisance_regressors.a0.b0-940d66ee-e46f-4907-9a61-2d4991e11514.pklz
200630-05:55:02,942 nipype.workflow ERROR:
could not run node: resting_preproc_A00040573_NFB3.nuisance_regressor_0_0.build_nuisance_regressors.a0.b0
200630-05:55:02,942 nipype.workflow INFO:
crashfile: /output/crash/crash-20200630-055322-root-build_nuisance_regressors.a0.b0-59b29047-36af-4094-8daa-9c4326a07c3a.pklz
200630-05:55:02,943 nipype.workflow ERROR:
could not run node: resting_preproc_A00040573_NFB3.nuisance_regressor_2_0.build_nuisance_regressors.a0.b1
200630-05:55:02,943 nipype.workflow INFO:
crashfile: /output/crash/crash-20200630-055331-root-build_nuisance_regressors.a0.b1-b5b3503d-fd78-407b-9a17-3189c20f39af.pklz
200630-05:55:02,943 nipype.workflow ERROR:
could not run node: resting_preproc_A00040573_NFB3.nuisance_regressor_1_0.build_nuisance_regressors.a0.b1
200630-05:55:02,943 nipype.workflow INFO:
crashfile: /output/crash/crash-20200630-055341-root-build_nuisance_regressors.a0.b1-f58424c3-5685-494b-be02-a002aa50068e.pklz
200630-05:55:02,944 nipype.workflow ERROR:
could not run node: resting_preproc_A00040573_NFB3.nuisance_regressor_0_0.build_nuisance_regressors.a0.b1
200630-05:55:02,944 nipype.workflow INFO:
crashfile: /output/crash/crash-20200630-055350-root-build_nuisance_regressors.a0.b1-9fe0a841-93a4-40bf-891d-3ec929b12163.pklz
200630-05:55:02,944 nipype.workflow ERROR:
could not run node: resting_preproc_A00040573_NFB3.nuisance_regressor_2_0.build_nuisance_regressors.a0.b2
200630-05:55:02,944 nipype.workflow INFO:
crashfile: /output/crash/crash-20200630-055359-root-build_nuisance_regressors.a0.b2-e353ed8e-fd86-447a-b5a3-248eb1daa6bf.pklz
200630-05:55:02,945 nipype.workflow ERROR:
could not run node: resting_preproc_A00040573_NFB3.nuisance_regressor_1_0.build_nuisance_regressors.a0.b2
200630-05:55:02,945 nipype.workflow INFO:
crashfile: /output/crash/crash-20200630-055408-root-build_nuisance_regressors.a0.b2-2c8c4803-dffe-49fd-a35a-230712eb2af6.pklz
200630-05:55:02,945 nipype.workflow ERROR:
could not run node: resting_preproc_A00040573_NFB3.nuisance_regressor_0_0.build_nuisance_regressors.a0.b2
200630-05:55:02,945 nipype.workflow INFO:
crashfile: /output/crash/crash-20200630-055417-root-build_nuisance_regressors.a0.b2-1eaae723-a7b8-4ddb-b6d8-4e85c123de54.pklz
200630-05:55:02,946 nipype.workflow INFO:
***********************************
200630-05:55:03,12 nipype.workflow INFO:


Error of subject workflow resting_preproc_A00040573_NFB3

CPAC run error:

 Pipeline configuration: test_out_CPACv162
 Subject workflow: resting_preproc_A00040573_NFB3
 Elapsed run time (minutes): 98.08629939953487
 Timing information saved in /output/log/cpac_individual_timing_test_out_CPACv162.csv
 System time of start:      2020-06-30 04:17:03

```
```Python
File "/code/CPAC/nuisance/nuisance.py", line 167, in gather_nuisance
  regressor_length))
  
ValueError: Number of time points in /home/circleci/project/outputs/working/resting_preproc_A00040573_NFB3/nuisance_regressor_2_0/_scan_MSIT/_selector_WM-2mmE-M_CSF-2mmE-M_aC-CSF+WM-2mm-DPC5_M-SDB_P-2_BP-B0.009-T0.08_C-I-1+2-FD-P0.5/CerebrospinalFluid_mean/roi_stats.csv (0) is inconsistent with length of functional file /home/circleci/project/outputs/working/resting_preproc_A00040573_NFB3/func_preproc_afni_mean_3dvolreg_0/_scan_MSIT/func_normalize/sub-A00040573_ses-NFB3_task-MSIT_bold_calc_tshift_resample_volreg_calc_maths.nii.gz (198)
```
```Python
File "/code/CPAC/nuisance/nuisance.py", line 167, in gather_nuisance
  regressor_length))

ValueError: Number of time points in /output/working/resting_preproc_A00040573_NFB3/nuisance_regressor_0_0/_scan_MSIT/_selector_WM-2mmE-M_CSF-2mmE-M_aC-CSF+WM-2mm-DPC5_G-M_M-SDB_P-2_BP-B0.009-T0.08_C-I-1+2-FD-P0.5/CerebrospinalFluid_mean/roi_stats.csv (0) is inconsistent with length of functional file /output/working/resting_preproc_A00040573_NFB3/func_preproc_afni_mean_3dvolreg_0/_scan_MSIT/func_normalize/sub-A00040573_ses-NFB3_task-MSIT_bold_calc_tshift_resample_volreg_calc_maths.nii.gz (198)

```
```Python
File "/code/CPAC/nuisance/nuisance.py", line 167, in gather_nuisance
  regressor_length))

ValueError: Number of time points in /output/working/resting_preproc_A00040573_NFB3/nuisance_regressor_2_0/_scan_PEER1/_selector_WM-2mmE-M_CSF-2mmE-M_aC-CSF+WM-2mm-DPC5_M-SDB_P-2_BP-B0.009-T0.08_C-I-1+2-FD-P0.5/CerebrospinalFluid_mean/roi_stats.csv (0) is inconsistent with length of functional file /output/working/resting_preproc_A00040573_NFB3/func_preproc_afni_mean_3dvolreg_0/_scan_PEER1/func_normalize/sub-A00040573_ses-NFB3_task-PEER1_bold_calc_tshift_resample_volreg_calc_maths.nii.gz (54)
```
```Python
File "/code/CPAC/nuisance/nuisance.py", line 167, in gather_nuisance
  regressor_length))

ValueError: Number of time points in /output/working/resting_preproc_A00040573_NFB3/nuisance_regressor_2_0/_scan_PEER2/_selector_WM-2mmE-M_CSF-2mmE-M_aC-CSF+WM-2mm-DPC5_M-SDB_P-2_BP-B0.009-T0.08_C-I-1+2-FD-P0.5/CerebrospinalFluid_mean/roi_stats.csv (0) is inconsistent with length of functional file /output/working/resting_preproc_A00040573_NFB3/func_preproc_afni_mean_3dvolreg_0/_scan_PEER2/func_normalize/sub-A00040573_ses-NFB3_task-PEER2_bold_calc_tshift_resample_volreg_calc_maths.nii.gz (54)
```

#### Participant 19

[‚ìà Singularity](https://app.circleci.com/pipelines/github/shnizzedy/C-PAC/98/workflows/87b2ac35-aabc-428c-9fea-9b38cf0488db/jobs/657/artifacts)
[üê≥ Docker](https://app.circleci.com/pipelines/github/shnizzedy/C-PAC/98/workflows/87b2ac35-aabc-428c-9fea-9b38cf0488db/jobs/652/artifacts)

```BASH
200630-03:18:36,25 nipype.workflow INFO:
	 [Node] Finished "resting_preproc_A00040640_NFB3.sinker_0_qc___mni_normalized_anatomical_a".
200630-03:18:36,26 nipype.workflow INFO:
	 ***********************************
200630-03:18:36,26 nipype.workflow ERROR:
	 could not run node: resting_preproc_A00040640_NFB3.func_gather_0.check_for_s3.b2
200630-03:18:36,26 nipype.workflow INFO:
	 crashfile: /output/crash/crash-20200630-000224-root-check_for_s3.b2-897acc1e-f24d-485d-a4bf-9b13eb869e29.pklz
200630-03:18:36,28 nipype.workflow INFO:
	 ***********************************
200630-03:18:36,391 nipype.workflow INFO:
	 

Error of subject workflow resting_preproc_A00040640_NFB3

CPAC run error:

    Pipeline configuration: test_out_CPACv162
    Subject workflow: resting_preproc_A00040640_NFB3
    Elapsed run time (minutes): 196.53913532098133
    Timing information saved in /output/log/cpac_individual_timing_test_out_CPACv162.csv
    System time of start:      2020-06-30 00:02:09
```
```Python
ipype version 1.1.2
Traceback (most recent call last):

  File "/usr/local/miniconda/lib/python3.7/site-packages/nipype/pipeline/plugins/linear.py", line 44, in run
    node.run(updatehash=updatehash)

  File "/usr/local/miniconda/lib/python3.7/site-packages/nipype/pipeline/engine/nodes.py", line 471, in run
    result = self._run_interface(execute=True)

  File "/usr/local/miniconda/lib/python3.7/site-packages/nipype/pipeline/engine/nodes.py", line 555, in _run_interface
    return self._run_command(execute)

  File "/usr/local/miniconda/lib/python3.7/site-packages/nipype/pipeline/engine/nodes.py", line 635, in _run_command
    result = self._interface.run(cwd=outdir)

  File "/usr/local/miniconda/lib/python3.7/site-packages/nipype/interfaces/base/core.py", line 521, in run
    runtime = self._run_interface(runtime)

  File "/code/CPAC/utils/interfaces/function.py", line 152, in _run_interface
    out = function_handle(**args)

  File "/code/CPAC/utils/datasource.py", line 498, in check_for_s3
    % (local_path, len(img_nii.shape)))

OSError: File: /output/working/fcp-indi/data/Projects/RocklandSample/RawDataBIDS/sub-A00040640/ses-NFB3/func/sub-A00040640_ses-NFB3_task-PEER2_bold.nii.gz must be a functional image with 4 dimensions but 3 dimensions found!
```

---

:email: Emailed results and image to Columbia team.

</div>

### fix Singularity recipe

[{% octicon issue-opened height:12 class:"right left" aria-label:"issue opened" %} #1310](https://github.com/FCP-INDI/C-PAC/issues/1310) / [{% octicon git-pull-request height:12 class:"right left" aria-label:PR %} #1311](https://github.com/FCP-INDI/C-PAC/pull/1311)

### review Habanero <sup>2</sup>/<sub>2</sub>
<table class="conversation"><tr><td>Lisa</td><td markdown="1">
I'm not sure exactly what's going on here (below)- I think it has to do with my python or singularity related environment, but it's what comes out when I try to open any of my pklz.

Additionally, I ran the first (non motion-y) kid with a lower threshold of 0.3 and came back with about the same crash files- the main one still being on building the regressors.
I've also put these in the drive as well, but I guess we sort of already figured out that the threshold doesn't seem to be the issue exactly.

```Python
Traceback (most recent call last):

  File "/rigel/home/lg2942/anaconda/envs/cpac/lib/python3.6/site-packages/urllib3/connectionpool.py", line 677, in urlopen

    chunked=chunked,

  File "/rigel/home/lg2942/anaconda/envs/cpac/lib/python3.6/site-packages/urllib3/connectionpool.py", line 392, in _make_request

    conn.request(method, url, **httplib_request_kw)

  File "/rigel/home/lg2942/anaconda/envs/cpac/lib/python3.6/http/client.py", line 1262, in request

    self._send_request(method, url, body, headers, encode_chunked)

  File "/rigel/home/lg2942/anaconda/envs/cpac/lib/python3.6/http/client.py", line 1308, in _send_request

    self.endheaders(body, encode_chunked=encode_chunked)

  File "/rigel/home/lg2942/anaconda/envs/cpac/lib/python3.6/http/client.py", line 1257, in endheaders

    self._send_output(message_body, encode_chunked=encode_chunked)

  File "/rigel/home/lg2942/anaconda/envs/cpac/lib/python3.6/http/client.py", line 1036, in _send_output

    self.send(msg)

  File "/rigel/home/lg2942/anaconda/envs/cpac/lib/python3.6/http/client.py", line 974, in send

    self.connect()

  File "/rigel/home/lg2942/anaconda/envs/cpac/lib/python3.6/site-packages/docker/transport/unixconn.py", line 43, in connect

    sock.connect(self.unix_socket)

FileNotFoundError: [Errno 2] No such file or directory


During handling of the above exception, another exception occurred:


Traceback (most recent call last):

  File "/rigel/home/lg2942/anaconda/envs/cpac/lib/python3.6/site-packages/requests/adapters.py", line 449, in send

    timeout=timeout

  File "/rigel/home/lg2942/anaconda/envs/cpac/lib/python3.6/site-packages/urllib3/connectionpool.py", line 725, in urlopen

    method, url, error=e, _pool=self, _stacktrace=sys.exc_info()[2]

  File "/rigel/home/lg2942/anaconda/envs/cpac/lib/python3.6/site-packages/urllib3/util/retry.py", line 403, in increment

    raise six.reraise(type(error), error, _stacktrace)

  File "/rigel/home/lg2942/anaconda/envs/cpac/lib/python3.6/site-packages/urllib3/packages/six.py", line 734, in reraise

    raise value.with_traceback(tb)

  File "/rigel/home/lg2942/anaconda/envs/cpac/lib/python3.6/site-packages/urllib3/connectionpool.py", line 677, in urlopen

    chunked=chunked,

  File "/rigel/home/lg2942/anaconda/envs/cpac/lib/python3.6/site-packages/urllib3/connectionpool.py", line 392, in _make_request

    conn.request(method, url, **httplib_request_kw)

  File "/rigel/home/lg2942/anaconda/envs/cpac/lib/python3.6/http/client.py", line 1262, in request

    self._send_request(method, url, body, headers, encode_chunked)

  File "/rigel/home/lg2942/anaconda/envs/cpac/lib/python3.6/http/client.py", line 1308, in _send_request

    self.endheaders(body, encode_chunked=encode_chunked)

  File "/rigel/home/lg2942/anaconda/envs/cpac/lib/python3.6/http/client.py", line 1257, in endheaders

    self._send_output(message_body, encode_chunked=encode_chunked)

  File "/rigel/home/lg2942/anaconda/envs/cpac/lib/python3.6/http/client.py", line 1036, in _send_output

    self.send(msg)

  File "/rigel/home/lg2942/anaconda/envs/cpac/lib/python3.6/http/client.py", line 974, in send

    self.connect()

  File "/rigel/home/lg2942/anaconda/envs/cpac/lib/python3.6/site-packages/docker/transport/unixconn.py", line 43, in connect

    sock.connect(self.unix_socket)

urllib3.exceptions.ProtocolError: ('Connection aborted.', FileNotFoundError(2, 'No such file or directory'))


During handling of the above exception, another exception occurred:


Traceback (most recent call last):

  File "/rigel/home/lg2942/anaconda/envs/cpac/lib/python3.6/site-packages/cpac/__main__.py", line 209, in main

    *original_args[1:]

  File "/rigel/home/lg2942/anaconda/envs/cpac/lib/python3.6/site-packages/cpac/__main__.py", line 286, in main

    Backends(**arg_vars).read_crash(

  File "/rigel/home/lg2942/anaconda/envs/cpac/lib/python3.6/site-packages/cpac/backends/__init__.py", line 27, in Backends

    }[platform](**kwargs)

  File "/rigel/home/lg2942/anaconda/envs/cpac/lib/python3.6/site-packages/cpac/backends/docker.py", line 12, in __init__

    self.client.ping()

  File "/rigel/home/lg2942/anaconda/envs/cpac/lib/python3.6/site-packages/docker/client.py", line 187, in ping

    return self.api.ping(*args, **kwargs)

  File "/rigel/home/lg2942/anaconda/envs/cpac/lib/python3.6/site-packages/docker/api/daemon.py", line 166, in ping

    return self._result(self._get(self._url('/_ping'))) == 'OK'

  File "/rigel/home/lg2942/anaconda/envs/cpac/lib/python3.6/site-packages/docker/utils/decorators.py", line 46, in inner

    return f(self, *args, **kwargs)

  File "/rigel/home/lg2942/anaconda/envs/cpac/lib/python3.6/site-packages/docker/api/client.py", line 230, in _get

    return self.get(url, **self._set_request_timeout(kwargs))

  File "/rigel/home/lg2942/anaconda/envs/cpac/lib/python3.6/site-packages/requests/sessions.py", line 543, in get

    return self.request('GET', url, **kwargs)

  File "/rigel/home/lg2942/anaconda/envs/cpac/lib/python3.6/site-packages/requests/sessions.py", line 530, in request

    resp = self.send(prep, **send_kwargs)

  File "/rigel/home/lg2942/anaconda/envs/cpac/lib/python3.6/site-packages/requests/sessions.py", line 643, in send

    r = adapter.send(request, **kwargs)

  File "/rigel/home/lg2942/anaconda/envs/cpac/lib/python3.6/site-packages/requests/adapters.py", line 498, in send

    raise ConnectionError(err, request=request)

requests.exceptions.ConnectionError: ('Connection aborted.', FileNotFoundError(2, 'No such file or directory'))


During handling of the above exception, another exception occurred:


Traceback (most recent call last):

  File "/rigel/home/lg2942/anaconda/envs/cpac/lib/python3.6/site-packages/cpac/backends/singularity.py", line 33, in __init__

    pull_folder=pwd

  File "/rigel/home/lg2942/anaconda/envs/cpac/lib/python3.6/site-packages/spython/main/pull.py", line 94, in pull

    self._run_command(cmd, capture=capture, quiet=quiet)

  File "/rigel/home/lg2942/anaconda/envs/cpac/lib/python3.6/site-packages/spython/main/base/command.py", line 133, in run_command

    cmd, sudo=sudo, capture=capture, quiet=quiet, sudo_options=sudo_options

  File "/rigel/home/lg2942/anaconda/envs/cpac/lib/python3.6/site-packages/spython/utils/terminal.py", line 182, in run_command

    process = subprocess.Popen(cmd, stderr=subprocess.PIPE, stdout=stdout)

  File "/rigel/home/lg2942/anaconda/envs/cpac/lib/python3.6/subprocess.py", line 729, in __init__

    restore_signals, start_new_session)

  File "/rigel/home/lg2942/anaconda/envs/cpac/lib/python3.6/subprocess.py", line 1364, in _execute_child

    raise child_exception_type(errno_num, err_msg, err_filename)

FileNotFoundError: [Errno 2] No such file or directory: 'singularity': 'singularity'


During handling of the above exception, another exception occurred:


Traceback (most recent call last):

  File "/rigel/home/lg2942/anaconda/envs/cpac/lib/python3.6/site-packages/cpac/backends/singularity.py", line 39, in __init__

    pull_folder=pwd

  File "/rigel/home/lg2942/anaconda/envs/cpac/lib/python3.6/site-packages/spython/main/pull.py", line 94, in pull

    self._run_command(cmd, capture=capture, quiet=quiet)

  File "/rigel/home/lg2942/anaconda/envs/cpac/lib/python3.6/site-packages/spython/main/base/command.py", line 133, in run_command

    cmd, sudo=sudo, capture=capture, quiet=quiet, sudo_options=sudo_options

  File "/rigel/home/lg2942/anaconda/envs/cpac/lib/python3.6/site-packages/spython/utils/terminal.py", line 182, in run_command

    process = subprocess.Popen(cmd, stderr=subprocess.PIPE, stdout=stdout)

  File "/rigel/home/lg2942/anaconda/envs/cpac/lib/python3.6/subprocess.py", line 729, in __init__

    restore_signals, start_new_session)

  File "/rigel/home/lg2942/anaconda/envs/cpac/lib/python3.6/subprocess.py", line 1364, in _execute_child

    raise child_exception_type(errno_num, err_msg, err_filename)

FileNotFoundError: [Errno 2] No such file or directory: 'singularity': 'singularity'

During handling of the above exception, another exception occurred:

Traceback (most recent call last):

  File "/rigel/home/lg2942/anaconda/envs/cpac/bin/cpac", line 8, in <module>
  
    sys.exit(run())

  File "/rigel/home/lg2942/anaconda/envs/cpac/lib/python3.6/site-packages/cpac/__main__.py", line 293, in run
  
    main(sys.argv)

  File "/rigel/home/lg2942/anaconda/envs/cpac/lib/python3.6/site-packages/cpac/__main__.py", line 216, in main

    *original_args[1:]
    
  File "/rigel/home/lg2942/anaconda/envs/cpac/lib/python3.6/site-packages/cpac/__main__.py", line 286, in main
  
    Backends(**arg_vars).read_crash(
      
  File "/rigel/home/lg2942/anaconda/envs/cpac/lib/python3.6/site-packages/cpac/backends/__init__.py", line 27, in Backends
  
    }[platform](**kwargs)
    
  File "/rigel/home/lg2942/anaconda/envs/cpac/lib/python3.6/site-packages/cpac/backends/singularity.py", line 42, in __init__
  
    raise OSError("Could not connect to Singularity")
    
OSError: Could not connect to Singularity
```
</td></tr><tr><td>Jon</td><td markdown="1">
What command are you running to get the traceback in this email? It looks like `cpac-py` can't find `singularity` in your path. Does `which singularity` find it?

The sinker crashfiles are just [this bug](https://github.com/FCP-INDI/C-PAC/issues/1260).

```Python
AttributeError: 'SameFileError' object has no attribute 'message'
```

It doesn't hurt anything besides creating unnecessary crashfiles. We've got [a fix](https://github.com/FCP-INDI/C-PAC/pull/1313), but it's not included in the image I sent today.

The other crashfile is

```Python
ValueError: Regressor type Censor specified in selectors but the corresponding file was not found!
```

which *should* be resolved in the image I sent over this afternoon.

Has the previous image worked for any of your data?
</td></tr></table>