---
title: "crash-20201112-220559-av2902-check_for_s3.b1-0402782f-c3bb-4161-b2c7-9b6857c8ff78.pklz"
slug: "crash-20201112-220559-av2902-check_for_s3.b1-0402782f-c3bb-4161-b2c7-9b6857c8ff78.pklz"
categories: [files]
author: Anna Vannucci
date: 2020-11-16
---
```BASH
resting_preproc_sub-026_ses-2.func_gather_0.check_for_s3
```
```Python
Traceback (most recent call last):

  File "/usr/local/miniconda/lib/python3.7/site-packages/nipype/pipeline/engine/nodes.py", line 471, in run
    result = self._run_interface(execute=True)

  File "/usr/local/miniconda/lib/python3.7/site-packages/nipype/pipeline/engine/nodes.py", line 555, in _run_interface
    return self._run_command(execute)

  File "/usr/local/miniconda/lib/python3.7/site-packages/nipype/pipeline/engine/nodes.py", line 652, in _run_command
    dirs2keep=dirs2keep)

  File "/usr/local/miniconda/lib/python3.7/site-packages/nipype/pipeline/engine/utils.py", line 1511, in clean_working_directory
    os.remove(f)

FileNotFoundError: [Errno 2] No such file or directory: '/outputs/tmp/resting_preproc_sub-026_ses-2/func_gather_0/_scan_depletion_run-2/check_for_s3/.proc-23199_time-1605236759.2470667_freq-1.00'


During handling of the above exception, another exception occurred:


Traceback (most recent call last):

  File "/usr/local/miniconda/lib/python3.7/site-packages/nipype/pipeline/plugins/linear.py", line 44, in run
    node.run(updatehash=updatehash)

  File "/usr/local/miniconda/lib/python3.7/site-packages/nipype/pipeline/engine/nodes.py", line 475, in run
    os.remove(hashfile_unfinished)

FileNotFoundError: [Errno 2] No such file or directory: '/outputs/tmp/resting_preproc_sub-026_ses-2/func_gather_0/_scan_depletion_run-2/check_for_s3/_0xd635c7f011be09a2537baed33c3280cd_unfinished.json'
```